INFO:telegram.ext.updater:Received signal 2 (SIGINT), stopping...
WARNING:telegram.ext.updater:Exiting immediately!
INFO:telegram.ext.updater:Received signal 2 (SIGINT), stopping...
WARNING:telegram.ext.updater:Exiting immediately!
INFO:root:The bot has started!
INFO:root:The bot has started!
INFO:telegram.ext.updater:Received signal 2 (SIGINT), stopping...
WARNING:telegram.ext.updater:Exiting immediately!
INFO:root:The bot has started!
ERROR:telegram.ext.dispatcher:No error handlers are registered, logging exception.
Traceback (most recent call last):
  File "/Users/artemhejfec/проекты/HEFABOT/myhefabot/env/lib/python3.7/site-packages/telegram/ext/dispatcher.py", line 340, in process_update
    handler.handle_update(update, self, check, context)
  File "/Users/artemhejfec/проекты/HEFABOT/myhefabot/env/lib/python3.7/site-packages/telegram/ext/handler.py", line 119, in handle_update
    return self.callback(update, context)
  File "bot.py", line 16, in speaks_to_user
    text = update.message.text
AttributeError: 'NoneType' object has no attribute 'text'
INFO:telegram.ext.updater:Received signal 2 (SIGINT), stopping...
WARNING:telegram.ext.updater:Exiting immediately!
INFO:root:The bot has started!
INFO:telegram.ext.updater:Received signal 2 (SIGINT), stopping...
WARNING:telegram.ext.updater:Exiting immediately!
INFO:root:The bot has started!
INFO:telegram.ext.updater:Received signal 2 (SIGINT), stopping...
WARNING:telegram.ext.updater:Exiting immediately!
INFO:root:The bot has started!
INFO:root:The bot has started!
ERROR:telegram.ext.dispatcher:No error handlers are registered, logging exception.
Traceback (most recent call last):
  File "/Users/artemhejfec/проекты/HEFABOT/myhefabot/env/lib/python3.7/site-packages/telegram/ext/dispatcher.py", line 340, in process_update
    handler.handle_update(update, self, check, context)
  File "/Users/artemhejfec/проекты/HEFABOT/myhefabot/env/lib/python3.7/site-packages/telegram/ext/handler.py", line 119, in handle_update
    return self.callback(update, context)
  File "bot.py", line 42, in checking_number
    update.message.reply_text(message)
AttributeError: 'NoneType' object has no attribute 'reply_text'
ERROR:telegram.ext.dispatcher:No error handlers are registered, logging exception.
Traceback (most recent call last):
  File "/Users/artemhejfec/проекты/HEFABOT/myhefabot/env/lib/python3.7/site-packages/telegram/ext/dispatcher.py", line 340, in process_update
    handler.handle_update(update, self, check, context)
  File "/Users/artemhejfec/проекты/HEFABOT/myhefabot/env/lib/python3.7/site-packages/telegram/ext/handler.py", line 119, in handle_update
    return self.callback(update, context)
  File "bot.py", line 42, in checking_number
    message = "Please enter a number."
AttributeError: 'NoneType' object has no attribute 'reply_text'
INFO:telegram.ext.updater:Received signal 2 (SIGINT), stopping...
WARNING:telegram.ext.updater:Exiting immediately!
INFO:root:The bot has started!
ERROR:telegram.ext.dispatcher:No error handlers are registered, logging exception.
Traceback (most recent call last):
  File "/Users/artemhejfec/проекты/HEFABOT/myhefabot/env/lib/python3.7/site-packages/telegram/ext/dispatcher.py", line 340, in process_update
    handler.handle_update(update, self, check, context)
  File "/Users/artemhejfec/проекты/HEFABOT/myhefabot/env/lib/python3.7/site-packages/telegram/ext/handler.py", line 119, in handle_update
    return self.callback(update, context)
  File "bot.py", line 43, in checking_number
    update.message.reply_text(message)
AttributeError: 'NoneType' object has no attribute 'reply_text'
INFO:telegram.ext.updater:Received signal 2 (SIGINT), stopping...
WARNING:telegram.ext.updater:Exiting immediately!
INFO:root:The bot has started!
INFO:telegram.ext.updater:Received signal 2 (SIGINT), stopping...
WARNING:telegram.ext.updater:Exiting immediately!
INFO:root:The bot has started!
INFO:telegram.ext.updater:Received signal 2 (SIGINT), stopping...
WARNING:telegram.ext.updater:Exiting immediately!
INFO:root:The bot has started!
INFO:telegram.ext.updater:Received signal 2 (SIGINT), stopping...
WARNING:telegram.ext.updater:Exiting immediately!
INFO:root:The bot has started!
INFO:telegram.ext.updater:Received signal 2 (SIGINT), stopping...
WARNING:telegram.ext.updater:Exiting immediately!
INFO:root:The bot has started!
INFO:telegram.ext.updater:Received signal 2 (SIGINT), stopping...
WARNING:telegram.ext.updater:Exiting immediately!
INFO:root:The bot has started!
ERROR:telegram.ext.dispatcher:No error handlers are registered, logging exception.
Traceback (most recent call last):
  File "/Users/artemhejfec/проекты/HEFABOT/myhefabot/env/lib/python3.7/site-packages/telegram/vendor/ptb_urllib3/urllib3/connectionpool.py", line 402, in _make_request
    six.raise_from(e, None)
  File "<string>", line 2, in raise_from
  File "/Users/artemhejfec/проекты/HEFABOT/myhefabot/env/lib/python3.7/site-packages/telegram/vendor/ptb_urllib3/urllib3/connectionpool.py", line 398, in _make_request
    httplib_response = conn.getresponse()
  File "/Library/Frameworks/Python.framework/Versions/3.7/lib/python3.7/http/client.py", line 1321, in getresponse
    response.begin()
  File "/Library/Frameworks/Python.framework/Versions/3.7/lib/python3.7/http/client.py", line 296, in begin
    version, status, reason = self._read_status()
  File "/Library/Frameworks/Python.framework/Versions/3.7/lib/python3.7/http/client.py", line 257, in _read_status
    line = str(self.fp.readline(_MAXLINE + 1), "iso-8859-1")
  File "/Library/Frameworks/Python.framework/Versions/3.7/lib/python3.7/socket.py", line 589, in readinto
    return self._sock.recv_into(b)
  File "/Library/Frameworks/Python.framework/Versions/3.7/lib/python3.7/ssl.py", line 1052, in recv_into
    return self.read(nbytes, buffer)
  File "/Library/Frameworks/Python.framework/Versions/3.7/lib/python3.7/ssl.py", line 911, in read
    return self._sslobj.read(len, buffer)
socket.timeout: The read operation timed out

During handling of the above exception, another exception occurred:

Traceback (most recent call last):
  File "/Users/artemhejfec/проекты/HEFABOT/myhefabot/env/lib/python3.7/site-packages/telegram/utils/request.py", line 224, in _request_wrapper
    resp = self._con_pool.request(*args, **kwargs)
  File "/Users/artemhejfec/проекты/HEFABOT/myhefabot/env/lib/python3.7/site-packages/telegram/vendor/ptb_urllib3/urllib3/request.py", line 70, in request
    **urlopen_kw)
  File "/Users/artemhejfec/проекты/HEFABOT/myhefabot/env/lib/python3.7/site-packages/telegram/vendor/ptb_urllib3/urllib3/request.py", line 148, in request_encode_body
    return self.urlopen(method, url, **extra_kw)
  File "/Users/artemhejfec/проекты/HEFABOT/myhefabot/env/lib/python3.7/site-packages/telegram/vendor/ptb_urllib3/urllib3/poolmanager.py", line 244, in urlopen
    response = conn.urlopen(method, u.request_uri, **kw)
  File "/Users/artemhejfec/проекты/HEFABOT/myhefabot/env/lib/python3.7/site-packages/telegram/vendor/ptb_urllib3/urllib3/connectionpool.py", line 666, in urlopen
    _stacktrace=sys.exc_info()[2])
  File "/Users/artemhejfec/проекты/HEFABOT/myhefabot/env/lib/python3.7/site-packages/telegram/vendor/ptb_urllib3/urllib3/util/retry.py", line 347, in increment
    raise six.reraise(type(error), error, _stacktrace)
  File "/Users/artemhejfec/проекты/HEFABOT/myhefabot/env/lib/python3.7/site-packages/telegram/vendor/ptb_urllib3/urllib3/packages/six.py", line 686, in reraise
    raise value
  File "/Users/artemhejfec/проекты/HEFABOT/myhefabot/env/lib/python3.7/site-packages/telegram/vendor/ptb_urllib3/urllib3/connectionpool.py", line 617, in urlopen
    chunked=chunked)
  File "/Users/artemhejfec/проекты/HEFABOT/myhefabot/env/lib/python3.7/site-packages/telegram/vendor/ptb_urllib3/urllib3/connectionpool.py", line 405, in _make_request
    exc_cls=ReadTimeoutError)
  File "/Users/artemhejfec/проекты/HEFABOT/myhefabot/env/lib/python3.7/site-packages/telegram/vendor/ptb_urllib3/urllib3/connectionpool.py", line 321, in _raise_timeout
    raise exc_cls(*args)
telegram.vendor.ptb_urllib3.urllib3.exceptions.ReadTimeoutError: HTTPSConnectionPool(host='api.telegram.org', port=443): Read timed out. (read timeout=5.0)

During handling of the above exception, another exception occurred:

Traceback (most recent call last):
  File "/Users/artemhejfec/проекты/HEFABOT/myhefabot/env/lib/python3.7/site-packages/telegram/ext/dispatcher.py", line 340, in process_update
    handler.handle_update(update, self, check, context)
  File "/Users/artemhejfec/проекты/HEFABOT/myhefabot/env/lib/python3.7/site-packages/telegram/ext/handler.py", line 119, in handle_update
    return self.callback(update, context)
  File "bot.py", line 43, in checking_number
    else:
  File "/Users/artemhejfec/проекты/HEFABOT/myhefabot/env/lib/python3.7/site-packages/telegram/message.py", line 515, in reply_text
    return self.bot.send_message(self.chat_id, *args, **kwargs)
  File "<decorator-gen-2>", line 2, in send_message
  File "/Users/artemhejfec/проекты/HEFABOT/myhefabot/env/lib/python3.7/site-packages/telegram/bot.py", line 67, in decorator
    result = func(*args, **kwargs)
  File "/Users/artemhejfec/проекты/HEFABOT/myhefabot/env/lib/python3.7/site-packages/telegram/bot.py", line 348, in send_message
    timeout=timeout, **kwargs)
  File "/Users/artemhejfec/проекты/HEFABOT/myhefabot/env/lib/python3.7/site-packages/telegram/bot.py", line 175, in _message
    result = self._request.post(url, data, timeout=timeout)
  File "/Users/artemhejfec/проекты/HEFABOT/myhefabot/env/lib/python3.7/site-packages/telegram/utils/request.py", line 333, in post
    **urlopen_kwargs)
  File "/Users/artemhejfec/проекты/HEFABOT/myhefabot/env/lib/python3.7/site-packages/telegram/utils/request.py", line 226, in _request_wrapper
    raise TimedOut()
telegram.error.TimedOut: Timed out
INFO:telegram.ext.updater:Received signal 2 (SIGINT), stopping...
WARNING:telegram.ext.updater:Exiting immediately!
INFO:root:The bot has started!
